Workbook
Name bpx_eigenkapitalquote: Stuetzstellen!$A$6:$A$13
Name bpy_eigenkapitalquote: Stuetzstellen!$B$6:$B$13
Name bpx_kapitaldienstfaehigkeit_inkl_neu: Stuetzstellen!$A$17:$A$24
Name bpy_kapitaldienstfaehigkeit_inkl_neu: Stuetzstellen!$B$17:$B$24
Name bpx_dynamischer_verschuldungsgrad: Stuetzstellen!$A$28:$A$37
Name bpy_dynamischer_verschuldungsgrad: Stuetzstellen!$B$28:$B$37
Name bpx_ebit_marge: Stuetzstellen!$A$41:$A$49
Name bpy_ebit_marge: Stuetzstellen!$B$41:$B$49
Name bpx_liquiditaet_2_grades: Stuetzstellen!$A$53:$A$60
Name bpy_liquiditaet_2_grades: Stuetzstellen!$B$53:$B$60
Name bpx_zinsdeckungsgrad: Stuetzstellen!$A$64:$A$70
Name bpy_zinsdeckungsgrad: Stuetzstellen!$B$64:$B$70
Name bpx_kontokorrent_auslastung: Stuetzstellen!$A$74:$A$81
Name bpy_kontokorrent_auslastung: Stuetzstellen!$B$74:$B$81
Name bpx_bwa_age_months: Stuetzstellen!$A$85:$A$91
Name bpy_bwa_age_months: Stuetzstellen!$B$85:$B$91
Name bpx_creditreform_bonitaetsindex: Stuetzstellen!$A$95:$A$103
Name bpy_creditreform_bonitaetsindex: Stuetzstellen!$B$95:$B$103
Name bpx_zahlungsverhalten: Stuetzstellen!$A$107:$A$108
Name bpy_zahlungsverhalten: Stuetzstellen!$B$107:$B$108

Sheet Anleitung
A1: Scorecard-Pruefblatt
A3: Wozu dieses Blatt / What this workbook is for
A4: Es rechnet die Bewertung der Engine mit Excel-Formeln nach. Jede Zahl ist nachvollziehbar,
A5: keine Zelle ist ein exportiertes Ergebnis. Wer die Engine pruefen will, prueft sie hier.
A7: It reimplements the engine's scoring in live Excel formulas. Nothing is a pasted result.
A9: So benutzen Sie es / How to use it
A10: 1. Blatt 'Eingaben': Spalte C ist Ihr eigener Fall. Ueberschreiben Sie die Werte.
A11: Spalten D bis I sind die Musterfaelle und sollten unveraendert bleiben.
A12: 2. Blatt 'Kennzahlen': alle Zwischengroessen und Kennzahlen, Formel fuer Formel.
A13: 3. Blatt 'Scorecard': die zehn Faktoren, ihre Punkte, Gewichte, der Gesamtscore und das Band.
A14: 4. Blatt 'Abgleich': Excel gegen Engine, Faktor fuer Faktor, fuer jeden Musterfall.
A15: Dort muss ueberall 'OK' stehen. Steht dort eine Abweichung, ist eine der beiden Seiten falsch.
... A30: Bei jeder Aenderung an scorecard.py oder ratios.py neu erzeugen.

Sheet Stuetzstellen
A1: Stuetzstellen der Faktoren / factor breakpoints
A2: Zwischen den Punkten wird linear interpoliert, ausserhalb wird gekappt.
A4: Eigenkapitalquote (wirtschaftlich) | C4: Gewicht 20% | D4: Wirtschaftliches EK inkl. nachrangiger Gesellschafterdarlehen. Stuetzstellen 14,8/35,1/56,9% = Quartile der Bundesbank-Statistik.
A5: Wert | B5: Punkte
A6: -0.2 | B6: 0
A7: 0 | B7: 25
A8: 0.05 | B8: 38
A9: 0.148 | B9: 58
A10: 0.351 | B10: 70
A11: 0.569 | B11: 82
A12: 0.8 | B12: 95
A13: 1 | B13: 100
A15: Kapitaldienstfaehigkeit inkl. neuer Finanzierung (DSCR) | C15: Gewicht 20% | D15: EBITDA / (Zins + Tilgung), inkl. des beantragten Engagements.
A16: Wert | B16: Punkte
A17: 0.7 | B17: 0
A18: 0.9 | B18: 12
A19: 1 | B19: 25
A20: 1.1 | B20: 42
A21: 1.2 | B21: 58
A22: 1.3 | B22: 72
A23: 1.5 | B23: 88
A24: 2 | B24: 100
A26: Dynamischer Verschuldungsgrad (Nettoverschuldung / EBITDA) | C26: Gewicht 15%
A27: Wert | B27: Punkte
A28: 0 | B28: 100
A29: 1 | B29: 95
A30: 2 | B30: 88
A31: 3 | B31: 75
A32: 3.5 | B32: 65
A33: 4 | B33: 55
A34: 5 | B34: 38
A35: 6 | B35: 25
A36: 8 | B36: 10
A37: 12 | B37: 0
A39: EBIT-Marge | C39: Gewicht 12% | D39: Stuetzstellen 1,35/4,75/9,95% = Bundesbank-Quartile des Ergebnisses vor Steuern, um 0,5 Punkte auf EBIT-Basis angehoben.
A40: Wert | B40: Punkte
A41: -0.1 | B41: 0
A42: -0.05 | B42: 12
A43: -0.02 | B43: 28
A44: 0 | B44: 45
...

Sheet Eingaben
A1: Eingaben / inputs
A2: Spalte C ueberschreiben. Musterfaelle nicht aendern -- der Abgleich haengt daran.
A4: Position | B4: Hinweis / note | C4: Ihr Fall | D4: Mueller Praezisionstechnik GmbH | E4: Nordlicht Handel GmbH & Co. KG | F4: Gastro Rheinblick GmbH | G4: Datenwerk Consulting GmbH | H4: Ihrig Sanitaer- und Heizungstechnik GmbH | I4: Hoffmann Medizintechnik GmbH
A5: AKTIVA (Bilanz, HGB §266) | B5: Assets
A6: Immaterielle Vermoegensgegenstaende | B6: Intangibles incl. goodwill | C6: 60000 | D6: 60000 | E6: 0 | F6: 180000 | G6: 95000 | H6: 0 | I6: 140000
A7: Sachanlagen | B7: Tangible fixed assets | C7: 2100000 | D7: 2100000 | E7: 420000 | F7: 1450000 | G7: 210000 | H7: 1000000 | I7: 3200000
A8: Finanzanlagen | B8: Financial assets | C8: 0 | D8: 0 | E8: 0 | F8: 0 | G8: 0 | H8: 0 | I8: 260000
A9: Vorraete | B9: Inventory | C9: 780000 | D9: 780000 | E9: 1850000 | F9: 85000 | G9: 0 | H9: 240000 | I9: 1180000
A10: Forderungen aus L+L | B10: Trade receivables | C10: 1150000 | D10: 1150000 | E10: 2240000 | F10: 45000 | G10: 1420000 | H10: 520000 | I10: 1340000
A11: Sonstige Vermoegensgegenstaende | B11: Other assets | C11: 90000 | D11: 90000 | E11: 70000 | F11: 0 | G11: 85000 | H11: 0 | I11: 0
A12: Wertpapiere | B12: Securities | C12: 0 | D12: 0 | E12: 0 | F12: 0 | G12: 0 | H12: 0 | I12: 0
A13: Liquide Mittel | B13: Cash and bank | C13: 180000 | D13: 180000 | E13: 60000 | F13: 22000 | G13: 640000 | H13: 310000 | I13: 1850000
A14: Aktive Rechnungsabgrenzung | B14: Prepaid expenses | C14: 25000 | D14: 25000 | E14: 0 | F14: 0 | G14: 0 | H14: 0 | I14: 0
A15: PASSIVA (Bilanz) | B15: Liabilities and equity
A16: Gezeichnetes Kapital | B16: Subscribed capital | C16: 25000 | D16: 25000 | E16: 50000 | F16: 25000 | G16: 50000 | H16: 25000 | I16: 200000
A17: Kapitalruecklage | B17: Capital reserve | C17: 0 | D17: 0 | E17: 0 | F17: 0 | G17: 150000 | H17: 0 | I17: 400000
A18: Gewinnruecklagen | B18: Retained earnings reserve | C18: 95000 | D18: 95000 | E18: 220000 | F18: 0 | G18: 320000 | H18: 232000 | I18: 2763000
A19: Gewinnvortrag / Verlustvortrag | B19: Profit carried forward (may be negative) | C19: 95000 | D19: 95000 | E19: 130000 | F19: -137000 | G19: 260000 | H19: 140000 | I19: 610000
A20: Jahresueberschuss laut Bilanz | B20: Net result as shown in equity | C20: 230000 | D20: 230000 | E20: 116000 | F20: -458000 | G20: 485000 | H20: 96000 | I20: 967000
A21: Ausstehende Einlagen | B21: Unpaid contributions (deducted) | C21: 0 | D21: 0 | E21: 0 | F21: 0 | G21: 0 | H21: 0 | I21: 0
A22: Rueckstellungen | B22: Provisions | C22: 350000 | D22: 350000 | E22: 145000 | F22: 120000 | G22: 285000 | H22: 165000 | I22: 690000
A23: Pensionsrueckstellungen | B23: Pension provisions | C23: 0 | D23: 0 | E23: 0 | F23: 0 | G23: 0 | H23: 0 | I23: 0
A24: Verb. Kreditinstitute < 1 Jahr | B24: Bank debt, short term | C24: 420000 | D24: 420000 | E24: 1480000 | F24: 380000 | G24: 0 | H24: 90000 | I24: 120000
A25: Verb. Kreditinstitute > 1 Jahr | B25: Bank debt, long term | C25: 1250000 | D25: 1250000 | E25: 320000 | F25: 1180000 | G25: 180000 | H25: 560000 | I25: 1340000
A26: Verbindlichkeiten aus L+L | B26: Trade payables | C26: 680000 | D26: 680000 | E26: 1690000 | F26: 295000 | G26: 340000 | H26: 322000 | I26: 690000
A27: Sonstige Verbindlichkeiten < 1 Jahr | B27: Other liabilities, short term | C27: 240000 | D27: 240000 | E27: 489000 | F27: 377000 | G27: 380000 | H27: 120000 | I27: 190000
... A29: Passive Rechnungsabgrenzung | B29: Deferred income | C29: 0 | D29: 0 | E29: 0 | F29: 0 | G29: 0 | H29: 0 | I29: 0
A30: SONDERPOSITIONEN | B30: The items that decide fixability
A31: Gesellschafterdarlehen | B31: Shareholder loan | C31: 600000 | D31: 600000 | E31: 0 | F31: 0 | G31: 0 | H31: 320000 | I31: 0
A32: Rangruecktritt vorhanden (1 = ja) | B32: Subordination agreement in place | C32: 0 | D32: 0 | E32: 0 | F32: 0 | G32: 0 | H32: 0 | I32: 0
A33: Kontokorrentlinie (Limit) | B33: Overdraft facility limit | C33: 500000 | D33: 500000 | E33: 1500000 | F33: 400000 | G33: 300000 | H33: 250000 | I33: 800000
A34: Kontokorrent-Inanspruchnahme | B34: Overdraft drawn | C34: 420000 | D34: 420000 | E34: 1460000 | F34: 380000 | G34: 0 | H34: 90000 | I34: 0
A35: Leasingverpflichtungen | B35: Off-balance-sheet leasing | C35: 0 | D35: 0 | E35: 0 | F35: 0 | G35: 0 | H35: 0 | I35: 0
A36: GUV (HGB §275, Gesamtkostenverfahren) | B36: Income statement
A37: Periodenlaenge in Monaten | B37: 1-12; a mid-year BWA is annualised | C37: 12 | D37: 12 | E37: 12 | F37: 12 | G37: 12 | H37: 12 | I37: 12
A38: Umsatzerloese | B38: Revenue | C38: 8200000 | D38: 8200000 | E38: 11400000 | F38: 2980000 | G38: 7850000 | H38: 3640000 | I38: 14600000
A39: Bestandsveraenderungen | B39: Change in inventories | C39: 0 | D39: 0 | E39: 0 | F39: 0 | G39: 0 | H39: 0 | I39: 0
A40: Sonstige betriebliche Ertraege | B40: Other operating income | C40: 45000 | D40: 45000 | E40: 0 | F40: 0 | G40: 0 | H40: 0 | I40: 85000
A41: Materialaufwand | B41: Cost of materials | C41: 4180000 | D41: 4180000 | E41: 8950000 | F41: 1090000 | G41: 1180000 | H41: 1580000 | I41: 6100000
A42: Personalaufwand | B42: Personnel expenses | C42: 2650000 | D42: 2650000 | E42: 1420000 | F42: 1520000 | G42: 5100000 | H42: 1480000 | I42: 5180000
...

Sheet Kennzahlen
A1: Zwischengroessen und Kennzahlen / derived figures and ratios
A2: Alles Formeln. Diese Seite ist die eigentliche Nachrechnung von models.py und ratios.py.
A4: Groesse | B4: Formel / formula | C4: Ihr Fall | D4: Mueller Praezisionstechnik GmbH | E4: Nordlicht Handel GmbH & Co. KG | F4: Gastro Rheinblick GmbH | G4: Datenwerk Consulting GmbH | H4: Ihrig Sanitaer- und Heizungstechnik GmbH | I4: Hoffmann Medizintechnik GmbH
A5: ZWISCHENGROESSEN (models.py) | B5: Derived figures
A6: Annualisierungsfaktor | B6: 12 / Periodenmonate | C6: =12/Eingaben!C37 | D6: =12/Eingaben!D37 | E6: =12/Eingaben!E37 | F6: =12/Eingaben!F37 | G6: =12/Eingaben!G37 | H6: =12/Eingaben!H37 | I6: =12/Eingaben!I37
A7: Anlagevermoegen | B7: immat + Sachanlagen + Finanzanlagen | C7: =Eingaben!C6+Eingaben!C7+Eingaben!C8 | D7: =Eingaben!D6+Eingaben!D7+Eingaben!D8 | E7: =Eingaben!E6+Eingaben!E7+Eingaben!E8 | F7: =Eingaben!F6+Eingaben!F7+Eingaben!F8 | G7: =Eingaben!G6+Eingaben!G7+Eingaben!G8 | H7: =Eingaben!H6+Eingaben!H7+Eingaben!H8 | I7: =Eingaben!I6+Eingaben!I7+Eingaben!I8
A8: Umlaufvermoegen | B8: Vorraete + Ford. + sonst. VG + WP + liquide Mittel | C8: =Eingaben!C9+Eingaben!C10+Eingaben!C11+Eingaben!C12+Eingaben!C13 | D8: =Eingaben!D9+Eingaben!D10+Eingaben!D11+Eingaben!D12+Eingaben!D13 | E8: =Eingaben!E9+Eingaben!E10+Eingaben!E11+Eingaben!E12+Eingaben!E13 | F8: =Eingaben!F9+Eingaben!F10+Eingaben!F11+Eingaben!F12+Eingaben!F13 | G8: =Eingaben!G9+Eingaben!G10+Eingaben!G11+Eingaben!G12+Eingaben!G13 | H8: =Eingaben!H9+Eingaben!H10+Eingaben!H11+Eingaben!H12+Eingaben!H13 | I8: =Eingaben!I9+Eingaben!I10+Eingaben!I11+Eingaben!I12+Eingaben!I13
A9: Bilanzsumme (Aktiva) | B9: AV + UV + ARAP | C9: =C7+C8+Eingaben!C14 | D9: =D7+D8+Eingaben!D14 | E9: =E7+E8+Eingaben!E14 | F9: =F7+F8+Eingaben!F14 | G9: =G7+G8+Eingaben!G14 | H9: =H7+H8+Eingaben!H14 | I9: =I7+I8+Eingaben!I14
A10: Summe Passiva (Probe) | B10: EK + Rueckst. + Verb. + PRAP + Ges.darlehen | C10: =C13+Eingaben!C22+Eingaben!C23+Eingaben!C24+Eingaben!C25+Eingaben!C26+Eingaben!C27+Eingaben!C28+Eingaben!C31+Eingaben!C29 | D10: =D13+Eingaben!D22+Eingaben!D23+Eingaben!D24+Eingaben!D25+Eingaben!D26+Eingaben!D27+Eingaben!D28+Eingaben!D31+Eingaben!D29 | E10: =E13+Eingaben!E22+Eingaben!E23+Eingaben!E24+Eingaben!E25+Eingaben!E26+Eingaben!E27+Eingaben!E28+Eingaben!E31+Eingaben!E29 | F10: =F13+Eingaben!F22+Eingaben!F23+Eingaben!F24+Eingaben!F25+Eingaben!F26+Eingaben!F27+Eingaben!F28+Eingaben!F31+Eingaben!F29 | G10: =G13+Eingaben!G22+Eingaben!G23+Eingaben!G24+Eingaben!G25+Eingaben!G26+Eingaben!G27+Eingaben!G28+Eingaben!G31+Eingaben!G29 | H10: =H13+Eingaben!H22+Eingaben!H23+Eingaben!H24+Eingaben!H25+Eingaben!H26+Eingaben!H27+Eingaben!H28+Eingaben!H31+Eingaben!H29 | I10: =I13+Eingaben!I22+Eingaben!I23+Eingaben!I24+Eingaben!I25+Eingaben!I26+Eingaben!I27+Eingaben!I28+Eingaben!I31+Eingaben!I29
A11: Bilanzprobe: Aktiva - Passiva | B11: Muss ~0 sein, sonst blockiert die Engine | C11: =C9-C10 | D11: =D9-D10 | E11: =E9-E10 | F11: =F9-F10 | G11: =G9-G10 | H11: =H9-H10 | I11: =I9-I10
A12: Bilanz ausgeglichen? | B12: Toleranz: max(1 EUR; 0,5% der Bilanzsumme) | C12: =IF(ABS(C11)<=MAX(1,0.005*C9),"OK","FEHLER - Engine bricht ab") | D12: =IF(ABS(D11)<=MAX(1,0.005*D9),"OK","FEHLER - Engine bricht ab") | E12: =IF(ABS(E11)<=MAX(1,0.005*E9),"OK","FEHLER - Engine bricht ab") | F12: =IF(ABS(F11)<=MAX(1,0.005*F9),"OK","FEHLER - Engine bricht ab") | G12: =IF(ABS(G11)<=MAX(1,0.005*G9),"OK","FEHLER - Engine bricht ab") | H12: =IF(ABS(H11)<=MAX(1,0.005*H9),"OK","FEHLER - Engine bricht ab") | I12: =IF(ABS(I11)<=MAX(1,0.005*I9),"OK","FEHLER - Engine bricht ab")
A13: Bilanzielles Eigenkapital | B13: gez. Kapital + Ruecklagen + Vortrag + JUE - ausst. Einlagen | C13: =Eingaben!C16+Eingaben!C17+Eingaben!C18+Eingaben!C19+Eingaben!C20-Eingaben!C21 | D13: =Eingaben!D16+Eingaben!D17+Eingaben!D18+Eingaben!D19+Eingaben!D20-Eingaben!D21 | E13: =Eingaben!E16+Eingaben!E17+Eingaben!E18+Eingaben!E19+Eingaben!E20-Eingaben!E21 | F13: =Eingaben!F16+Eingaben!F17+Eingaben!F18+Eingaben!F19+Eingaben!F20-Eingaben!F21 | G13: =Eingaben!G16+Eingaben!G17+Eingaben!G18+Eingaben!G19+Eingaben!G20-Eingaben!G21 | H13: =Eingaben!H16+Eingaben!H17+Eingaben!H18+Eingaben!H19+Eingaben!H20-Eingaben!H21 | I13: =Eingaben!I16+Eingaben!I17+Eingaben!I18+Eingaben!I19+Eingaben!I20-Eingaben!I21
A14: Wirtschaftliches Eigenkapital | B14: + Gesellschafterdarlehen, wenn Rangruecktritt | C14: =C13+IF(Eingaben!C32=1,Eingaben!C31,0) | D14: =D13+IF(Eingaben!D32=1,Eingaben!D31,0) | E14: =E13+IF(Eingaben!E32=1,Eingaben!E31,0) | F14: =F13+IF(Eingaben!F32=1,Eingaben!F31,0) | G14: =G13+IF(Eingaben!G32=1,Eingaben!G31,0) | H14: =H13+IF(Eingaben!H32=1,Eingaben!H31,0) | I14: =I13+IF(Eingaben!I32=1,Eingaben!I31,0)
A15: Finanzverbindlichkeiten | B15: Bankschulden + Ges.darlehen ohne Rangruecktritt | C15: =Eingaben!C24+Eingaben!C25+IF(Eingaben!C32=1,0,Eingaben!C31) | D15: =Eingaben!D24+Eingaben!D25+IF(Eingaben!D32=1,0,Eingaben!D31) | E15: =Eingaben!E24+Eingaben!E25+IF(Eingaben!E32=1,0,Eingaben!E31) | F15: =Eingaben!F24+Eingaben!F25+IF(Eingaben!F32=1,0,Eingaben!F31) | G15: =Eingaben!G24+Eingaben!G25+IF(Eingaben!G32=1,0,Eingaben!G31) | H15: =Eingaben!H24+Eingaben!H25+IF(Eingaben!H32=1,0,Eingaben!H31) | I15: =Eingaben!I24+Eingaben!I25+IF(Eingaben!I32=1,0,Eingaben!I31)
A16: Nettofinanzverbindlichkeiten | B16: abzgl. liquide Mittel und Wertpapiere, min. 0 | C16: =MAX(0,C15-Eingaben!C13-Eingaben!C12) | D16: =MAX(0,D15-Eingaben!D13-Eingaben!D12) | E16: =MAX(0,E15-Eingaben!E13-Eingaben!E12) | F16: =MAX(0,F15-Eingaben!F13-Eingaben!F12) | G16: =MAX(0,G15-Eingaben!G13-Eingaben!G12) | H16: =MAX(0,H15-Eingaben!H13-Eingaben!H12) | I16: =MAX(0,I15-Eingaben!I13-Eingaben!I12)
A17: Kurzfristige Verbindlichkeiten | B17: Bank kurz + L+L + sonstige kurz | C17: =Eingaben!C24+Eingaben!C26+Eingaben!C27 | D17: =Eingaben!D24+Eingaben!D26+Eingaben!D27 | E17: =Eingaben!E24+Eingaben!E26+Eingaben!E27 | F17: =Eingaben!F24+Eingaben!F26+Eingaben!F27 | G17: =Eingaben!G24+Eingaben!G26+Eingaben!G27 | H17: =Eingaben!H24+Eingaben!H26+Eingaben!H27 | I17: =Eingaben!I24+Eingaben!I26+Eingaben!I27
A18: Langfristiges Kapital | B18: wirtsch. EK + Bank lang + sonst. lang + Pensionen | C18: =C14+Eingaben!C25+Eingaben!C28+Eingaben!C23 | D18: =D14+Eingaben!D25+Eingaben!D28+Eingaben!D23 | E18: =E14+Eingaben!E25+Eingaben!E28+Eingaben!E23 | F18: =F14+Eingaben!F25+Eingaben!F28+Eingaben!F23 | G18: =G14+Eingaben!G25+Eingaben!G28+Eingaben!G23 | H18: =H14+Eingaben!H25+Eingaben!H28+Eingaben!H23 | I18: =I14+Eingaben!I25+Eingaben!I28+Eingaben!I23
A19: ANNUALISIERTE GUV-GROESSEN (ratios.py) | B19: Flows, annualised
A20: Gesamtleistung | B20: Umsatz + Bestandsveraenderung + sonst. Ertraege | C20: =(Eingaben!C38+Eingaben!C39+Eingaben!C40)*C6 | D20: =(Eingaben!D38+Eingaben!D39+Eingaben!D40)*D6 | E20: =(Eingaben!E38+Eingaben!E39+Eingaben!E40)*E6 | F20: =(Eingaben!F38+Eingaben!F39+Eingaben!F40)*F6 | G20: =(Eingaben!G38+Eingaben!G39+Eingaben!G40)*G6 | H20: =(Eingaben!H38+Eingaben!H39+Eingaben!H40)*H6 | I20: =(Eingaben!I38+Eingaben!I39+Eingaben!I40)*I6
A21: Umsatz (annualisiert) | C21: =Eingaben!C38*C6 | D21: =Eingaben!D38*D6 | E21: =Eingaben!E38*E6 | F21: =Eingaben!F38*F6 | G21: =Eingaben!G38*G6 | H21: =Eingaben!H38*H6 | I21: =Eingaben!I38*I6
A22: EBITDA (annualisiert) | B22: Gesamtleistung - Material - Personal - sonst. Aufwand | C22: =C20-(Eingaben!C41+Eingaben!C42+Eingaben!C44)*C6 | D22: =D20-(Eingaben!D41+Eingaben!D42+Eingaben!D44)*D6 | E22: =E20-(Eingaben!E41+Eingaben!E42+Eingaben!E44)*E6 | F22: =F20-(Eingaben!F41+Eingaben!F42+Eingaben!F44)*F6 | G22: =G20-(Eingaben!G41+Eingaben!G42+Eingaben!G44)*G6 | H22: =H20-(Eingaben!H41+Eingaben!H42+Eingaben!H44)*H6 | I22: =I20-(Eingaben!I41+Eingaben!I42+Eingaben!I44)*I6
A23: EBIT (annualisiert) | B23: EBITDA - Abschreibungen | C23: =C22-Eingaben!C43*C6 | D23: =D22-Eingaben!D43*D6 | E23: =E22-Eingaben!E43*E6 | F23: =F22-Eingaben!F43*F6 | G23: =G22-Eingaben!G43*G6 | H23: =H22-Eingaben!H43*H6 | I23: =I22-Eingaben!I43*I6
A24: Zinsaufwand (annualisiert) | C24: =Eingaben!C46*C6 | D24: =Eingaben!D46*D6 | E24: =Eingaben!E46*E6 | F24: =Eingaben!F46*F6 | G24: =Eingaben!G46*G6 | H24: =Eingaben!H46*H6 | I24: =Eingaben!I46*I6
A25: Materialaufwand (annualisiert) | C25: =Eingaben!C41*C6 | D25: =Eingaben!D41*D6 | E25: =Eingaben!E41*E6 | F25: =Eingaben!F41*F6 | G25: =Eingaben!G41*G6 | H25: =Eingaben!H41*H6 | I25: =Eingaben!I41*I6
A26: Jahresueberschuss laut GuV | B26: EBIT + Zinsertrag - Zinsaufwand - Steuern (nicht annualisiert) | C26: =(C23/C6)+Eingaben!C45-Eingaben!C46-Eingaben!C47 | D26: =(D23/D6)+Eingaben!D45-Eingaben!D46-Eingaben!D47 | E26: =(E23/E6)+Eingaben!E45-Eingaben!E46-Eingaben!E47 | F26: =(F23/F6)+Eingaben!F45-Eingaben!F46-Eingaben!F47 | G26: =(G23/G6)+Eingaben!G45-Eingaben!G46-Eingaben!G47 | H26: =(H23/H6)+Eingaben!H45-Eingaben!H46-Eingaben!H47 | I26: =(I23/I6)+Eingaben!I45-Eingaben!I46-Eingaben!I47
A27: Ergebnis GuV = Ergebnis Bilanz? | B27: Nur bei 12-Monats-Periode geprueft | C27: =IF(Eingaben!C37<>12,"n/a (Rumpfperiode)",IF(ABS(C26-Eingaben!C20)<=MAX(1,0.002*C9),"OK","FEHLER - Engine bricht ab")) | D27: =IF(Eingaben!D37<>12,"n/a (Rumpfperiode)",IF(ABS(D26-Eingaben!D20)<=MAX(1,0.002*D9),"OK","FEHLER - Engine bricht ab")) | E27: =IF(Eingaben!E37<>12,"n/a (Rumpfperiode)",IF(ABS(E26-Eingaben!E20)<=MAX(1,0.002*E9),"OK","FEHLER - Engine bricht ab")) | F27: =IF(Eingaben!F37<>12,"n/a (Rumpfperiode)",IF(ABS(F26-Eingaben!F20)<=MAX(1,0.002*F9),"OK","FEHLER - Engine bricht ab")) | G27: =IF(Eingaben!G37<>12,"n/a (Rumpfperiode)",IF(ABS(G26-Eingaben!G20)<=MAX(1,0.002*G9),"OK","FEHLER - Engine bricht ab")) | H27: =IF(Eingaben!H37<>12,"n/a (Rumpfperiode)",IF(ABS(H26-Eingaben!H20)<=MAX(1,0.002*H9),"OK","FEHLER - Engine bricht ab")) | I27: =IF(Eingaben!I37<>12,"n/a (Rumpfperiode)",IF(ABS(I26-Eingaben!I20)<=MAX(1,0.002*I9),"OK","FEHLER - Engine bricht ab"))
A28: KAPITALDIENST | B28: Debt service
A29: Kapitaldienst (bestehend) | B29: Zinsen + Tilgung aus der Darlehensliste | C29: =Eingaben!C52+Eingaben!C53 | D29: =Eingaben!D52+Eingaben!D53 | E29: =Eingaben!E52+Eingaben!E53 | F29: =Eingaben!F52+Eingaben!F53 | G29: =Eingaben!G52+Eingaben!G53 | H29: =Eingaben!H52+Eingaben!H53 | I29: =Eingaben!I52+Eingaben!I53
A30: Annuitaet der neuen Finanzierung | B30: 6,5% p.a., Laufzeit wie beantragt (konservativ) | C30: =IF(Eingaben!C55<=0,0,Eingaben!C55*(0.065*(1+0.065)^MAX(1,Eingaben!C56))/((1+0.065)^MAX(1,Eingaben!C56)-1)) | D30: =IF(Eingaben!D55<=0,0,Eingaben!D55*(0.065*(1+0.065)^MAX(1,Eingaben!D56))/((1+0.065)^MAX(1,Eingaben!D56)-1)) | E30: =IF(Eingaben!E55<=0,0,Eingaben!E55*(0.065*(1+0.065)^MAX(1,Eingaben!E56))/((1+0.065)^MAX(1,Eingaben!E56)-1)) | F30: =IF(Eingaben!F55<=0,0,Eingaben!F55*(0.065*(1+0.065)^MAX(1,Eingaben!F56))/((1+0.065)^MAX(1,Eingaben!F56)-1)) | G30: =IF(Eingaben!G55<=0,0,Eingaben!G55*(0.065*(1+0.065)^MAX(1,Eingaben!G56))/((1+0.065)^MAX(1,Eingaben!G56)-1)) | H30: =IF(Eingaben!H55<=0,0,Eingaben!H55*(0.065*(1+0.065)^MAX(1,Eingaben!H56))/((1+0.065)^MAX(1,Eingaben!H56)-1)) | I30: =IF(Eingaben!I55<=0,0,Eingaben!I55*(0.065*(1+0.065)^MAX(1,Eingaben!I56))/((1+0.065)^MAX(1,Eingaben!I56)-1))
A31: Kapitaldienst inkl. neuer Finanzierung | C31: =C29+C30 | D31: =D29+D30 | E31: =E29+E30 | F31: =F29+F30 | G31: =G29+G30 | H31: =H29+H30 | I31: =I29+I30
A32: KENNZAHLEN (ratios.py) | B32: Ratios
A33: Eigenkapitalquote (wirtschaftlich) | B33: wirtsch. EK / Bilanzsumme -- Faktor 1 | C33: =IF(C9=0,"",C14/C9) | D33: =IF(D9=0,"",D14/D9) | E33: =IF(E9=0,"",E14/E9) | F33: =IF(F9=0,"",F14/F9) | G33: =IF(G9=0,"",G14/G9) | H33: =IF(H9=0,"",H14/H9) | I33: =IF(I9=0,"",I14/I9)
A34: Eigenkapitalquote (bilanziell) | B34: nachrichtlich | C34: =IF(C9=0,"",C13/C9) | D34: =IF(D9=0,"",D13/D9) | E34: =IF(E9=0,"",E13/E9) | F34: =IF(F9=0,"",F13/F9) | G34: =IF(G9=0,"",G13/G9) | H34: =IF(H9=0,"",H13/H9) | I34: =IF(I9=0,"",I13/I9)
A35: Anlagendeckungsgrad II | B35: langfr. Kapital / Anlagevermoegen -- Regel R06 | C35: =IF(C7=0,"",C18/C7) | D35: =IF(D7=0,"",D18/D7) | E35: =IF(E7=0,"",E18/E7) | F35: =IF(F7=0,"",F18/F7) | G35: =IF(G7=0,"",G18/G7) | H35: =IF(H7=0,"",H18/H7) | I35: =IF(I7=0,"",I18/I7)
A36: Dynamischer Verschuldungsgrad | B36: Nettoverschuldung / EBITDA -- Faktor 3 | C36: =IF(C22<=0,"",C16/C22) | D36: =IF(D22<=0,"",D16/D22) | E36: =IF(E22<=0,"",E16/E22) | F36: =IF(F22<=0,"",F16/F22) | G36: =IF(G22<=0,"",G16/G22) | H36: =IF(H22<=0,"",H16/H22) | I36: =IF(I22<=0,"",I16/I22)
A37: Kapitaldienstfaehigkeit (bestehend) | B37: EBITDA / Kapitaldienst | C37: =IF(C29<=0,"",C22/C29) | D37: =IF(D29<=0,"",D22/D29) | E37: =IF(E29<=0,"",E22/E29) | F37: =IF(F29<=0,"",F22/F29) | G37: =IF(G29<=0,"",G22/G29) | H37: =IF(H29<=0,"",H22/H29) | I37: =IF(I29<=0,"",I22/I29)
A38: Kapitaldienstfaehigkeit inkl. neu | B38: EBITDA / Kapitaldienst inkl. neu -- Faktor 2 | C38: =IF(C31<=0,"",C22/C31) | D38: =IF(D31<=0,"",D22/D31) | E38: =IF(E31<=0,"",E22/E31) | F38: =IF(F31<=0,"",F22/F31) | G38: =IF(G31<=0,"",G22/G31) | H38: =IF(H31<=0,"",H22/H31) | I38: =IF(I31<=0,"",I22/I31)
A39: Zinsdeckungsgrad | B39: EBIT / Zinsaufwand -- Faktor 6 | C39: =IF(C24=0,"",C23/C24) | D39: =IF(D24=0,"",D23/D24) | E39: =IF(E24=0,"",E23/E24) | F39: =IF(F24=0,"",F23/F24) | G39: =IF(G24=0,"",G23/G24) | H39: =IF(H24=0,"",H23/H24) | I39: =IF(I24=0,"",I23/I24)
A40: EBITDA-Marge | B40: nachrichtlich | C40: =IF(C21=0,"",C22/C21) | D40: =IF(D21=0,"",D22/D21) | E40: =IF(E21=0,"",E22/E21) | F40: =IF(F21=0,"",F22/F21) | G40: =IF(G21=0,"",G22/G21) | H40: =IF(H21=0,"",H22/H21) | I40: =IF(I21=0,"",I22/I21)
A41: EBIT-Marge | B41: EBIT / Umsatz -- Faktor 4 | C41: =IF(C21=0,"",C23/C21) | D41: =IF(D21=0,"",D23/D21) | E41: =IF(E21=0,"",E23/E21) | F41: =IF(F21=0,"",F23/F21) | G41: =IF(G21=0,"",G23/G21) | H41: =IF(H21=0,"",H23/H21) | I41: =IF(I21=0,"",I23/I21)
...

Sheet Scorecard
A1: Scorecard / scoring
A2: Je Fall zwei Spalten: der Rohwert und die daraus interpolierten Punkte (0-100).
A4: Faktor | B4: Gewicht | C4: Einheit | D4: Ihr Fall | E4: Punkte | F4: Beitrag | G4: Mueller Praezisionstechnik GmbH | H4: Punkte | I4: Beitrag | J4: Nordlicht Handel GmbH & Co. KG | K4: Punkte | L4: Beitrag | M4: Gastro Rheinblick GmbH | N4: Punkte | O4: Beitrag | P4: Datenwerk Consulting GmbH | Q4: Punkte | R4: Beitrag | S4: Ihrig Sanitaer- und Heizungstechnik GmbH | T4: Punkte | U4: Beitrag | V4: Hoffmann Medizintechnik GmbH | W4: Punkte | X4: Beitrag
A5: Eigenkapitalquote (wirtschaftlich) | B5: 0.2 | C5: percent | D5: =IF(Kennzahlen!C33="","",Kennzahlen!C33) | E5: =IF(NOT(ISNUMBER(D5)),"",IF(D5<=INDEX(bpx_eigenkapitalquote,1),INDEX(bpy_eigenkapitalquote,1),IF(D5>=INDEX(bpx_eigenkapitalquote,COUNT(bpx_eigenkapitalquote)),INDEX(bpy_eigenkapitalquote,COUNT(bpx_eigenkapitalquote)),INDEX(bpy_eigenkapitalquote,MATCH(D5,bpx_eigenkapitalquote,1))+(D5-INDEX(bpx_eigenkapitalquote,MATCH(D5,bpx_eigenkapitalquote,1)))/(INDEX(bpx_eigenkapitalquote,MATCH(D5,bpx_eigenkapitalquote,1)+1)-INDEX(bpx_eigenkapitalquote,MATCH(D5,bpx_eigenkapitalquote,1)))*(INDEX(bpy_eigenkapitalquote,MATCH(D5,bpx_eigenkapitalquote,1)+1)-INDEX(bpy_eigenkapitalquote,MATCH(D5,bpx_eigenkapitalquote,1)))))) | F5: =IF(ISNUMBER(E5),$B5*E5,0) | G5: =IF(Kennzahlen!D33="","",Kennzahlen!D33) | H5: =IF(NOT(ISNUMBER(G5)),"",IF(G5<=INDEX(bpx_eigenkapitalquote,1),INDEX(bpy_eigenkapitalquote,1),IF(G5>=INDEX(bpx_eigenkapitalquote,COUNT(bpx_eigenkapitalquote)),INDEX(bpy_eigenkapitalquote,COUNT(bpx_eigenkapitalquote)),INDEX(bpy_eigenkapitalquote,MATCH(G5,bpx_eigenkapitalquote,1))+(G5-INDEX(bpx_eigenkapitalquote,MATCH(G5,bpx_eigenkapitalquote,1)))/(INDEX(bpx_eigenkapitalquote,MATCH(G5,bpx_eigenkapitalquote,1)+1)-INDEX(bpx_eigenkapitalquote,MATCH(G5,bpx_eigenkapitalquote,1)))*(INDEX(bpy_eigenkapitalquote,MATCH(G5,bpx_eigenkapitalquote,1)+1)-INDEX(bpy_eigenkapitalquote,MATCH(G5,bpx_eigenkapitalquote,1)))))) | I5: =IF(ISNUMBER(H5),$B5*H5,0) | J5: =IF(Kennzahlen!E33="","",Kennzahlen!E33) | K5: =IF(NOT(ISNUMBER(J5)),"",IF(J5<=INDEX(bpx_eigenkapitalquote,1),INDEX(bpy_eigenkapitalquote,1),IF(J5>=INDEX(bpx_eigenkapitalquote,COUNT(bpx_eigenkapitalquote)),INDEX(bpy_eigenkapitalquote,COUNT(bpx_eigenkapitalquote)),INDEX(bpy_eigenkapitalquote,MATCH(J5,bpx_eigenkapitalquote,1))+(J5-INDEX(bpx_eigenkapitalquote,MATCH(J5,bpx_eigenkapitalquote,1)))/(INDEX(bpx_eigenkapitalquote,MATCH(J5,bpx_eigenkapitalquote,1)+1)-INDEX(bpx_eigenkapitalquote,MATCH(J5,bpx_eigenkapitalquote,1)))*(INDEX(bpy_eigenkapitalquote,MATCH(J5,bpx_eigenkapitalquote,1)+1)-INDEX(bpy_eigenkapitalquote,MATCH(J5,bpx_eigenkapitalquote,1)))))) | L5: =IF(ISNUMBER(K5),$B5*K5,0) | M5: =IF(Kennzahlen!F33="","",Kennzahlen!F33) | N5: =IF(NOT(ISNUMBER(M5)),"",IF(M5<=INDEX(bpx_eigenkapitalquote,1),INDEX(bpy_eigenkapitalquote,1),IF(M5>=INDEX(bpx_eigenkapitalquote,COUNT(bpx_eigenkapitalquote)),INDEX(bpy_eigenkapitalquote,COUNT(bpx_eigenkapitalquote)),INDEX(bpy_eigenkapitalquote,MATCH(M5,bpx_eigenkapitalquote,1))+(M5-INDEX(bpx_eigenkapitalquote,MATCH(M5,bpx_eigenkapitalquote,1)))/(INDEX(bpx_eigenkapitalquote,MATCH(M5,bpx_eigenkapitalquote,1)+1)-INDEX(bpx_eigenkapitalquote,MATCH(M5,bpx_eigenkapitalquote,1)))*(INDEX(bpy_eigenkapitalquote,MATCH(M5,bpx_eigenkapitalquote,1)+1)-INDEX(bpy_eigenkapitalquote,MATCH(M5,bpx_eigenkapitalquote,1)))))) | O5: =IF(ISNUMBER(N5),$B5*N5,0) | P5: =IF(Kennzahlen!G33="","",Kennzahlen!G33) | Q5: =IF(NOT(ISNUMBER(P5)),"",IF(P5<=INDEX(bpx_eigenkapitalquote,1),INDEX(bpy_eigenkapitalquote,1),IF(P5>=INDEX(bpx_eigenkapitalquote,COUNT(bpx_eigenkapitalquote)),INDEX(bpy_eigenkapitalquote,COUNT(bpx_eigenkapitalquote)),INDEX(bpy_eigenkapitalquote,MATCH(P5,bpx_eigenkapitalquote,1))+(P5-INDEX(bpx_eigenkapitalquote,MATCH(P5,bpx_eigenkapitalquote,1)))/(INDEX(bpx_eigenkapitalquote,MATCH(P5,bpx_eigenkapitalquote,1)+1)-INDEX(bpx_eigenkapitalquote,MATCH(P5,bpx_eigenkapitalquote,1)))*(INDEX(bpy_eigenkapitalquote,MATCH(P5,bpx_eigenkapitalquote,1)+1)-INDEX(bpy_eigenkapitalquote,MATCH(P5,bpx_eigenkapitalquote,1)))))) | R5: =IF(ISNUMBER(Q5),$B5*Q5,0) | S5: =IF(Kennzahlen!H33="","",Kennzahlen!H33) | T5: =IF(NOT(ISNUMBER(S5)),"",IF(S5<=INDEX(bpx_eigenkapitalquote,1),INDEX(bpy_eigenkapitalquote,1),IF(S5>=INDEX(bpx_eigenkapitalquote,COUNT(bpx_eigenkapitalquote)),INDEX(bpy_eigenkapitalquote,COUNT(bpx_eigenkapitalquote)),INDEX(bpy_eigenkapitalquote,MATCH(S5,bpx_eigenkapitalquote,1))+(S5-INDEX(bpx_eigenkapitalquote,MATCH(S5,bpx_eigenkapitalquote,1)))/(INDEX(bpx_eigenkapitalquote,MATCH(S5,bpx_eigenkapitalquote,1)+1)-INDEX(bpx_eigenkapitalquote,MATCH(S5,bpx_eigenkapitalquote,1)))*(INDEX(bpy_eigenkapitalquote,MATCH(S5,bpx_eigenkapitalquote,1)+1)-INDEX(bpy_eigenkapitalquote,MATCH(S5,bpx_eigenkapitalquote,1)))))) | U5: =IF(ISNUMBER(T5),$B5*T5,0) | V5: =IF(Kennzahlen!I33="","",Kennzahlen!I33) | W5: =IF(NOT(ISNUMBER(V5)),"",IF(V5<=INDEX(bpx_eigenkapitalquote,1),INDEX(bpy_eigenkapitalquote,1),IF(V5>=INDEX(bpx_eigenkapitalquote,COUNT(bpx_eigenkapitalquote)),INDEX(bpy_eigenkapitalquote,COUNT(bpx_eigenkapitalquote)),INDEX(bpy_eigenkapitalquote,MATCH(V5,bpx_eigenkapitalquote,1))+(V5-INDEX(bpx_eigenkapitalquote,MATCH(V5,bpx_eigenkapitalquote,1)))/(INDEX(bpx_eigenkapitalquote,MATCH(V5,bpx_eigenkapitalquote,1)+1)-INDEX(bpx_eigenkapitalquote,MATCH(V5,bpx_eigenkapitalquote,1)))*(INDEX(bpy_eigenkapitalquote,MATCH(V5,bpx_eigenkapitalquote,1)+1)-INDEX(bpy_eigenkapitalquote,MATCH(V5,bpx_eigenkapitalquote,1)))))) | X5: =IF(ISNUMBER(W5),$B5*W5,0)
A6: Kapitaldienstfaehigkeit inkl. neuer Finanzierung (DSCR) | B6: 0.2 | C6: x | D6: =IF(Kennzahlen!C38="","",Kennzahlen!C38) | E6: =IF(NOT(ISNUMBER(D6)),"",IF(D6<=INDEX(bpx_kapitaldienstfaehigkeit_inkl_neu,1),INDEX(bpy_kapitaldienstfaehigkeit_inkl_neu,1),IF(D6>=INDEX(bpx_kapitaldienstfaehigkeit_inkl_neu,COUNT(bpx_kapitaldienstfaehigkeit_inkl_neu)),INDEX(bpy_kapitaldienstfaehigkeit_inkl_neu,COUNT(bpx_kapitaldienstfaehigkeit_inkl_neu)),INDEX(bpy_kapitaldienstfaehigkeit_inkl_neu,MATCH(D6,bpx_kapitaldienstfaehigkeit_inkl_neu,1))+(D6-INDEX(bpx_kapitaldienstfaehigkeit_inkl_neu,MATCH(D6,bpx_kapitaldienstfaehigkeit_inkl_neu,1)))/(INDEX(bpx_kapitaldienstfaehigkeit_inkl_neu,MATCH(D6,bpx_kapitaldienstfaehigkeit_inkl_neu,1)+1)-INDEX(bpx_kapitaldienstfaehigkeit_inkl_neu,MATCH(D6,bpx_kapitaldienstfaehigkeit_inkl_neu,1)))*(INDEX(bpy_kapitaldienstfaehigkeit_inkl_neu,MATCH(D6,bpx_kapitaldienstfaehigkeit_inkl_neu,1)+1)-INDEX(bpy_kapitaldienstfaehigkeit_inkl_neu,MATCH(D6,bpx_kapitaldienstfaehigkeit_inkl_neu,1)))))) | F6: =IF(ISNUMBER(E6),$B6*E6,0) | G6: =IF(Kennzahlen!D38="","",Kennzahlen!D38) | H6: =IF(NOT(ISNUMBER(G6)),"",IF(G6<=INDEX(bpx_kapitaldienstfaehigkeit_inkl_neu,1),INDEX(bpy_kapitaldienstfaehigkeit_inkl_neu,1),IF(G6>=INDEX(bpx_kapitaldienstfaehigkeit_inkl_neu,COUNT(bpx_kapitaldienstfaehigkeit_inkl_neu)),INDEX(bpy_kapitaldienstfaehigkeit_inkl_neu,COUNT(bpx_kapitaldienstfaehigkeit_inkl_neu)),INDEX(bpy_kapitaldienstfaehigkeit_inkl_neu,MATCH(G6,bpx_kapitaldienstfaehigkeit_inkl_neu,1))+(G6-INDEX(bpx_kapitaldienstfaehigkeit_inkl_neu,MATCH(G6,bpx_kapitaldienstfaehigkeit_inkl_neu,1)))/(INDEX(bpx_kapitaldienstfaehigkeit_inkl_neu,MATCH(G6,bpx_kapitaldienstfaehigkeit_inkl_neu,1)+1)-INDEX(bpx_kapitaldienstfaehigkeit_inkl_neu,MATCH(G6,bpx_kapitaldienstfaehigkeit_inkl_neu,1)))*(INDEX(bpy_kapitaldienstfaehigkeit_inkl_neu,MATCH(G6,bpx_kapitaldienstfaehigkeit_inkl_neu,1)+1)-INDEX(bpy_kapitaldienstfaehigkeit_inkl_neu,MATCH(G6,bpx_kapitaldienstfaehigkeit_inkl_neu,1)))))) | I6: =IF(ISNUMBER(H6),$B6*H6,0) | J6: =IF(Kennzahlen!E38="","",Kennzahlen!E38) | K6: =IF(NOT(ISNUMBER(J6)),"",IF(J6<=INDEX(bpx_kapitaldienstfaehigkeit_inkl_neu,1),INDEX(bpy_kapitaldienstfaehigkeit_inkl_neu,1),IF(J6>=INDEX(bpx_kapitaldienstfaehigkeit_inkl_neu,COUNT(bpx_kapitaldienstfaehigkeit_inkl_neu)),INDEX(bpy_kapitaldienstfaehigkeit_inkl_neu,COUNT(bpx_kapitaldienstfaehigkeit_inkl_neu)),INDEX(bpy_kapitaldienstfaehigkeit_inkl_neu,MATCH(J6,bpx_kapitaldienstfaehigkeit_inkl_neu,1))+(J6-INDEX(bpx_kapitaldienstfaehigkeit_inkl_neu,MATCH(J6,bpx_kapitaldienstfaehigkeit_inkl_neu,1)))/(INDEX(bpx_kapitaldienstfaehigkeit_inkl_neu,MATCH(J6,bpx_kapitaldienstfaehigkeit_inkl_neu,1)+1)-INDEX(bpx_kapitaldienstfaehigkeit_inkl_neu,MATCH(J6,bpx_kapitaldienstfaehigkeit_inkl_neu,1)))*(INDEX(bpy_kapitaldienstfaehigkeit_inkl_neu,MATCH(J6,bpx_kapitaldienstfaehigkeit_inkl_neu,1)+1)-INDEX(bpy_kapitaldienstfaehigkeit_inkl_neu,MATCH(J6,bpx_kapitaldienstfaehigkeit_inkl_neu,1)))))) | L6: =IF(ISNUMBER(K6),$B6*K6,0) | M6: =IF(Kennzahlen!F38="","",Kennzahlen!F38) | N6: =IF(NOT(ISNUMBER(M6)),"",IF(M6<=INDEX(bpx_kapitaldienstfaehigkeit_inkl_neu,1),INDEX(bpy_kapitaldienstfaehigkeit_inkl_neu,1),IF(M6>=INDEX(bpx_kapitaldienstfaehigkeit_inkl_neu,COUNT(bpx_kapitaldienstfaehigkeit_inkl_neu)),INDEX(bpy_kapitaldienstfaehigkeit_inkl_neu,COUNT(bpx_kapitaldienstfaehigkeit_inkl_neu)),INDEX(bpy_kapitaldienstfaehigkeit_inkl_neu,MATCH(M6,bpx_kapitaldienstfaehigkeit_inkl_neu,1))+(M6-INDEX(bpx_kapitaldienstfaehigkeit_inkl_neu,MATCH(M6,bpx_kapitaldienstfaehigkeit_inkl_neu,1)))/(INDEX(bpx_kapitaldienstfaehigkeit_inkl_neu,MATCH(M6,bpx_kapitaldienstfaehigkeit_inkl_neu,1)+1)-INDEX(bpx_kapitaldienstfaehigkeit_inkl_neu,MATCH(M6,bpx_kapitaldienstfaehigkeit_inkl_neu,1)))*(INDEX(bpy_kapitaldienstfaehigkeit_inkl_neu,MATCH(M6,bpx_kapitaldienstfaehigkeit_inkl_neu,1)+1)-INDEX(bpy_kapitaldienstfaehigkeit_inkl_neu,MATCH(M6,bpx_kapitaldienstfaehigkeit_inkl_neu,1)))))) | O6: =IF(ISNUMBER(N6),$B6*N6,0) | P6: =IF(Kennzahlen!G38="","",Kennzahlen!G38) | Q6: =IF(NOT(ISNUMBER(P6)),"",IF(P6<=INDEX(bpx_kapitaldienstfaehigkeit_inkl_neu,1),INDEX(bpy_kapitaldienstfaehigkeit_inkl_neu,1),IF(P6>=INDEX(bpx_kapitaldienstfaehigkeit_inkl_neu,COUNT(bpx_kapitaldienstfaehigkeit_inkl_neu)),INDEX(bpy_kapitaldienstfaehigkeit_inkl_neu,COUNT(bpx_kapitaldienstfaehigkeit_inkl_neu)),INDEX(bpy_kapitaldienstfaehigkeit_inkl_neu,MATCH(P6,bpx_kapitaldienstfaehigkeit_inkl_neu,1))+(P6-INDEX(bpx_kapitaldienstfaehigkeit_inkl_neu,MATCH(P6,bpx_kapitaldienstfaehigkeit_inkl_neu,1)))/(INDEX(bpx_kapitaldienstfaehigkeit_inkl_neu,MATCH(P6,bpx_kapitaldienstfaehigkeit_inkl_neu,1)+1)-INDEX(bpx_kapitaldienstfaehigkeit_inkl_neu,MATCH(P6,bpx_kapitaldienstfaehigkeit_inkl_neu,1)))*(INDEX(bpy_kapitaldienstfaehigkeit_inkl_neu,MATCH(P6,bpx_kapitaldienstfaehigkeit_inkl_neu,1)+1)-INDEX(bpy_kapitaldienstfaehigkeit_inkl_neu,MATCH(P6,bpx_kapitaldienstfaehigkeit_inkl_neu,1)))))) | R6: =IF(ISNUMBER(Q6),$B6*Q6,0) | S6: =IF(Kennzahlen!H38="","",Kennzahlen!H38) | T6: =IF(NOT(ISNUMBER(S6)),"",IF(S6<=INDEX(bpx_kapitaldienstfaehigkeit_inkl_neu,1),INDEX(bpy_kapitaldienstfaehigkeit_inkl_neu,1),IF(S6>=INDEX(bpx_kapitaldienstfaehigkeit_inkl_neu,COUNT(bpx_kapitaldienstfaehigkeit_inkl_neu)),INDEX(bpy_kapitaldienstfaehigkeit_inkl_neu,COUNT(bpx_kapitaldienstfaehigkeit_inkl_neu)),INDEX(bpy_kapitaldienstfaehigkeit_inkl_neu,MATCH(S6,bpx_kapitaldienstfaehigkeit_inkl_neu,1))+(S6-INDEX(bpx_kapitaldienstfaehigkeit_inkl_neu,MATCH(S6,bpx_kapitaldienstfaehigkeit_inkl_neu,1)))/(INDEX(bpx_kapitaldienstfaehigkeit_inkl_neu,MATCH(S6,bpx_kapitaldienstfaehigkeit_inkl_neu,1)+1)-INDEX(bpx_kapitaldienstfaehigkeit_inkl_neu,MATCH(S6,bpx_kapitaldienstfaehigkeit_inkl_neu,1)))*(INDEX(bpy_kapitaldienstfaehigkeit_inkl_neu,MATCH(S6,bpx_kapitaldienstfaehigkeit_inkl_neu,1)+1)-INDEX(bpy_kapitaldienstfaehigkeit_inkl_neu,MATCH(S6,bpx_kapitaldienstfaehigkeit_inkl_neu,1)))))) | U6: =IF(ISNUMBER(T6),$B6*T6,0) | V6: =IF(Kennzahlen!I38="","",Kennzahlen!I38) | W6: =IF(NOT(ISNUMBER(V6)),"",IF(V6<=INDEX(bpx_kapitaldienstfaehigkeit_inkl_neu,1),INDEX(bpy_kapitaldienstfaehigkeit_inkl_neu,1),IF(V6>=INDEX(bpx_kapitaldienstfaehigkeit_inkl_neu,COUNT(bpx_kapitaldienstfaehigkeit_inkl_neu)),INDEX(bpy_kapitaldienstfaehigkeit_inkl_neu,COUNT(bpx_kapitaldienstfaehigkeit_inkl_neu)),INDEX(bpy_kapitaldienstfaehigkeit_inkl_neu,MATCH(V6,bpx_kapitaldienstfaehigkeit_inkl_neu,1))+(V6-INDEX(bpx_kapitaldienstfaehigkeit_inkl_neu,MATCH(V6,bpx_kapitaldienstfaehigkeit_inkl_neu,1)))/(INDEX(bpx_kapitaldienstfaehigkeit_inkl_neu,MATCH(V6,bpx_kapitaldienstfaehigkeit_inkl_neu,1)+1)-INDEX(bpx_kapitaldienstfaehigkeit_inkl_neu,MATCH(V6,bpx_kapitaldienstfaehigkeit_inkl_neu,1)))*(INDEX(bpy_kapitaldienstfaehigkeit_inkl_neu,MATCH(V6,bpx_kapitaldienstfaehigkeit_inkl_neu,1)+1)-INDEX(bpy_kapitaldienstfaehigkeit_inkl_neu,MATCH(V6,bpx_kapitaldienstfaehigkeit_inkl_neu,1)))))) | X6: =IF(ISNUMBER(W6),$B6*W6,0)
A7: Dynamischer Verschuldungsgrad (Nettoverschuldung / EBITDA) | B7: 0.15 | C7: x | D7: =IF(Kennzahlen!C36="","",Kennzahlen!C36) | E7: =IF(Kennzahlen!C22<=0,0,IF(NOT(ISNUMBER(D7)),"",IF(D7<=INDEX(bpx_dynamischer_verschuldungsgrad,1),INDEX(bpy_dynamischer_verschuldungsgrad,1),IF(D7>=INDEX(bpx_dynamischer_verschuldungsgrad,COUNT(bpx_dynamischer_verschuldungsgrad)),INDEX(bpy_dynamischer_verschuldungsgrad,COUNT(bpx_dynamischer_verschuldungsgrad)),INDEX(bpy_dynamischer_verschuldungsgrad,MATCH(D7,bpx_dynamischer_verschuldungsgrad,1))+(D7-INDEX(bpx_dynamischer_verschuldungsgrad,MATCH(D7,bpx_dynamischer_verschuldungsgrad,1)))/(INDEX(bpx_dynamischer_verschuldungsgrad,MATCH(D7,bpx_dynamischer_verschuldungsgrad,1)+1)-INDEX(bpx_dynamischer_verschuldungsgrad,MATCH(D7,bpx_dynamischer_verschuldungsgrad,1)))*(INDEX(bpy_dynamischer_verschuldungsgrad,MATCH(D7,bpx_dynamischer_verschuldungsgrad,1)+1)-INDEX(bpy_dynamischer_verschuldungsgrad,MATCH(D7,bpx_dynamischer_verschuldungsgrad,1))))))) | F7: =IF(ISNUMBER(E7),$B7*E7,0) | G7: =IF(Kennzahlen!D36="","",Kennzahlen!D36) | H7: =IF(Kennzahlen!D22<=0,0,IF(NOT(ISNUMBER(G7)),"",IF(G7<=INDEX(bpx_dynamischer_verschuldungsgrad,1),INDEX(bpy_dynamischer_verschuldungsgrad,1),IF(G7>=INDEX(bpx_dynamischer_verschuldungsgrad,COUNT(bpx_dynamischer_verschuldungsgrad)),INDEX(bpy_dynamischer_verschuldungsgrad,COUNT(bpx_dynamischer_verschuldungsgrad)),INDEX(bpy_dynamischer_verschuldungsgrad,MATCH(G7,bpx_dynamischer_verschuldungsgrad,1))+(G7-INDEX(bpx_dynamischer_verschuldungsgrad,MATCH(G7,bpx_dynamischer_verschuldungsgrad,1)))/(INDEX(bpx_dynamischer_verschuldungsgrad,MATCH(G7,bpx_dynamischer_verschuldungsgrad,1)+1)-INDEX(bpx_dynamischer_verschuldungsgrad,MATCH(G7,bpx_dynamischer_verschuldungsgrad,1)))*(INDEX(bpy_dynamischer_verschuldungsgrad,MATCH(G7,bpx_dynamischer_verschuldungsgrad,1)+1)-INDEX(bpy_dynamischer_verschuldungsgrad,MATCH(G7,bpx_dynamischer_verschuldungsgrad,1))))))) | I7: =IF(ISNUMBER(H7),$B7*H7,0) | J7: =IF(Kennzahlen!E36="","",Kennzahlen!E36) | K7: =IF(Kennzahlen!E22<=0,0,IF(NOT(ISNUMBER(J7)),"",IF(J7<=INDEX(bpx_dynamischer_verschuldungsgrad,1),INDEX(bpy_dynamischer_verschuldungsgrad,1),IF(J7>=INDEX(bpx_dynamischer_verschuldungsgrad,COUNT(bpx_dynamischer_verschuldungsgrad)),INDEX(bpy_dynamischer_verschuldungsgrad,COUNT(bpx_dynamischer_verschuldungsgrad)),INDEX(bpy_dynamischer_verschuldungsgrad,MATCH(J7,bpx_dynamischer_verschuldungsgrad,1))+(J7-INDEX(bpx_dynamischer_verschuldungsgrad,MATCH(J7,bpx_dynamischer_verschuldungsgrad,1)))/(INDEX(bpx_dynamischer_verschuldungsgrad,MATCH(J7,bpx_dynamischer_verschuldungsgrad,1)+1)-INDEX(bpx_dynamischer_verschuldungsgrad,MATCH(J7,bpx_dynamischer_verschuldungsgrad,1)))*(INDEX(bpy_dynamischer_verschuldungsgrad,MATCH(J7,bpx_dynamischer_verschuldungsgrad,1)+1)-INDEX(bpy_dynamischer_verschuldungsgrad,MATCH(J7,bpx_dynamischer_verschuldungsgrad,1))))))) | L7: =IF(ISNUMBER(K7),$B7*K7,0) | M7: =IF(Kennzahlen!F36="","",Kennzahlen!F36) | N7: =IF(Kennzahlen!F22<=0,0,IF(NOT(ISNUMBER(M7)),"",IF(M7<=INDEX(bpx_dynamischer_verschuldungsgrad,1),INDEX(bpy_dynamischer_verschuldungsgrad,1),IF(M7>=INDEX(bpx_dynamischer_verschuldungsgrad,COUNT(bpx_dynamischer_verschuldungsgrad)),INDEX(bpy_dynamischer_verschuldungsgrad,COUNT(bpx_dynamischer_verschuldungsgrad)),INDEX(bpy_dynamischer_verschuldungsgrad,MATCH(M7,bpx_dynamischer_verschuldungsgrad,1))+(M7-INDEX(bpx_dynamischer_verschuldungsgrad,MATCH(M7,bpx_dynamischer_verschuldungsgrad,1)))/(INDEX(bpx_dynamischer_verschuldungsgrad,MATCH(M7,bpx_dynamischer_verschuldungsgrad,1)+1)-INDEX(bpx_dynamischer_verschuldungsgrad,MATCH(M7,bpx_dynamischer_verschuldungsgrad,1)))*(INDEX(bpy_dynamischer_verschuldungsgrad,MATCH(M7,bpx_dynamischer_verschuldungsgrad,1)+1)-INDEX(bpy_dynamischer_verschuldungsgrad,MATCH(M7,bpx_dynamischer_verschuldungsgrad,1))))))) | O7: =IF(ISNUMBER(N7),$B7*N7,0) | P7: =IF(Kennzahlen!G36="","",Kennzahlen!G36) | Q7: =IF(Kennzahlen!G22<=0,0,IF(NOT(ISNUMBER(P7)),"",IF(P7<=INDEX(bpx_dynamischer_verschuldungsgrad,1),INDEX(bpy_dynamischer_verschuldungsgrad,1),IF(P7>=INDEX(bpx_dynamischer_verschuldungsgrad,COUNT(bpx_dynamischer_verschuldungsgrad)),INDEX(bpy_dynamischer_verschuldungsgrad,COUNT(bpx_dynamischer_verschuldungsgrad)),INDEX(bpy_dynamischer_verschuldungsgrad,MATCH(P7,bpx_dynamischer_verschuldungsgrad,1))+(P7-INDEX(bpx_dynamischer_verschuldungsgrad,MATCH(P7,bpx_dynamischer_verschuldungsgrad,1)))/(INDEX(bpx_dynamischer_verschuldungsgrad,MATCH(P7,bpx_dynamischer_verschuldungsgrad,1)+1)-INDEX(bpx_dynamischer_verschuldungsgrad,MATCH(P7,bpx_dynamischer_verschuldungsgrad,1)))*(INDEX(bpy_dynamischer_verschuldungsgrad,MATCH(P7,bpx_dynamischer_verschuldungsgrad,1)+1)-INDEX(bpy_dynamischer_verschuldungsgrad,MATCH(P7,bpx_dynamischer_verschuldungsgrad,1))))))) | R7: =IF(ISNUMBER(Q7),$B7*Q7,0) | S7: =IF(Kennzahlen!H36="","",Kennzahlen!H36) | T7: =IF(Kennzahlen!H22<=0,0,IF(NOT(ISNUMBER(S7)),"",IF(S7<=INDEX(bpx_dynamischer_verschuldungsgrad,1),INDEX(bpy_dynamischer_verschuldungsgrad,1),IF(S7>=INDEX(bpx_dynamischer_verschuldungsgrad,COUNT(bpx_dynamischer_verschuldungsgrad)),INDEX(bpy_dynamischer_verschuldungsgrad,COUNT(bpx_dynamischer_verschuldungsgrad)),INDEX(bpy_dynamischer_verschuldungsgrad,MATCH(S7,bpx_dynamischer_verschuldungsgrad,1))+(S7-INDEX(bpx_dynamischer_verschuldungsgrad,MATCH(S7,bpx_dynamischer_verschuldungsgrad,1)))/(INDEX(bpx_dynamischer_verschuldungsgrad,MATCH(S7,bpx_dynamischer_verschuldungsgrad,1)+1)-INDEX(bpx_dynamischer_verschuldungsgrad,MATCH(S7,bpx_dynamischer_verschuldungsgrad,1)))*(INDEX(bpy_dynamischer_verschuldungsgrad,MATCH(S7,bpx_dynamischer_verschuldungsgrad,1)+1)-INDEX(bpy_dynamischer_verschuldungsgrad,MATCH(S7,bpx_dynamischer_verschuldungsgrad,1))))))) | U7: =IF(ISNUMBER(T7),$B7*T7,0) | V7: =IF(Kennzahlen!I36="","",Kennzahlen!I36) | W7: =IF(Kennzahlen!I22<=0,0,IF(NOT(ISNUMBER(V7)),"",IF(V7<=INDEX(bpx_dynamischer_verschuldungsgrad,1),INDEX(bpy_dynamischer_verschuldungsgrad,1),IF(V7>=INDEX(bpx_dynamischer_verschuldungsgrad,COUNT(bpx_dynamischer_verschuldungsgrad)),INDEX(bpy_dynamischer_verschuldungsgrad,COUNT(bpx_dynamischer_verschuldungsgrad)),INDEX(bpy_dynamischer_verschuldungsgrad,MATCH(V7,bpx_dynamischer_verschuldungsgrad,1))+(V7-INDEX(bpx_dynamischer_verschuldungsgrad,MATCH(V7,bpx_dynamischer_verschuldungsgrad,1)))/(INDEX(bpx_dynamischer_verschuldungsgrad,MATCH(V7,bpx_dynamischer_verschuldungsgrad,1)+1)-INDEX(bpx_dynamischer_verschuldungsgrad,MATCH(V7,bpx_dynamischer_verschuldungsgrad,1)))*(INDEX(bpy_dynamischer_verschuldungsgrad,MATCH(V7,bpx_dynamischer_verschuldungsgrad,1)+1)-INDEX(bpy_dynamischer_verschuldungsgrad,MATCH(V7,bpx_dynamischer_verschuldungsgrad,1))))))) | X7: =IF(ISNUMBER(W7),$B7*W7,0)
A8: EBIT-Marge | B8: 0.12 | C8: percent | D8: =IF(Kennzahlen!C41="","",Kennzahlen!C41) | E8: =IF(NOT(ISNUMBER(D8)),"",IF(D8<=INDEX(bpx_ebit_marge,1),INDEX(bpy_ebit_marge,1),IF(D8>=INDEX(bpx_ebit_marge,COUNT(bpx_ebit_marge)),INDEX(bpy_ebit_marge,COUNT(bpx_ebit_marge)),INDEX(bpy_ebit_marge,MATCH(D8,bpx_ebit_marge,1))+(D8-INDEX(bpx_ebit_marge,MATCH(D8,bpx_ebit_marge,1)))/(INDEX(bpx_ebit_marge,MATCH(D8,bpx_ebit_marge,1)+1)-INDEX(bpx_ebit_marge,MATCH(D8,bpx_ebit_marge,1)))*(INDEX(bpy_ebit_marge,MATCH(D8,bpx_ebit_marge,1)+1)-INDEX(bpy_ebit_marge,MATCH(D8,bpx_ebit_marge,1)))))) | F8: =IF(ISNUMBER(E8),$B8*E8,0) | G8: =IF(Kennzahlen!D41="","",Kennzahlen!D41) | H8: =IF(NOT(ISNUMBER(G8)),"",IF(G8<=INDEX(bpx_ebit_marge,1),INDEX(bpy_ebit_marge,1),IF(G8>=INDEX(bpx_ebit_marge,COUNT(bpx_ebit_marge)),INDEX(bpy_ebit_marge,COUNT(bpx_ebit_marge)),INDEX(bpy_ebit_marge,MATCH(G8,bpx_ebit_marge,1))+(G8-INDEX(bpx_ebit_marge,MATCH(G8,bpx_ebit_marge,1)))/(INDEX(bpx_ebit_marge,MATCH(G8,bpx_ebit_marge,1)+1)-INDEX(bpx_ebit_marge,MATCH(G8,bpx_ebit_marge,1)))*(INDEX(bpy_ebit_marge,MATCH(G8,bpx_ebit_marge,1)+1)-INDEX(bpy_ebit_marge,MATCH(G8,bpx_ebit_marge,1)))))) | I8: =IF(ISNUMBER(H8),$B8*H8,0) | J8: =IF(Kennzahlen!E41="","",Kennzahlen!E41) | K8: =IF(NOT(ISNUMBER(J8)),"",IF(J8<=INDEX(bpx_ebit_marge,1),INDEX(bpy_ebit_marge,1),IF(J8>=INDEX(bpx_ebit_marge,COUNT(bpx_ebit_marge)),INDEX(bpy_ebit_marge,COUNT(bpx_ebit_marge)),INDEX(bpy_ebit_marge,MATCH(J8,bpx_ebit_marge,1))+(J8-INDEX(bpx_ebit_marge,MATCH(J8,bpx_ebit_marge,1)))/(INDEX(bpx_ebit_marge,MATCH(J8,bpx_ebit_marge,1)+1)-INDEX(bpx_ebit_marge,MATCH(J8,bpx_ebit_marge,1)))*(INDEX(bpy_ebit_marge,MATCH(J8,bpx_ebit_marge,1)+1)-INDEX(bpy_ebit_marge,MATCH(J8,bpx_ebit_marge,1)))))) | L8: =IF(ISNUMBER(K8),$B8*K8,0) | M8: =IF(Kennzahlen!F41="","",Kennzahlen!F41) | N8: =IF(NOT(ISNUMBER(M8)),"",IF(M8<=INDEX(bpx_ebit_marge,1),INDEX(bpy_ebit_marge,1),IF(M8>=INDEX(bpx_ebit_marge,COUNT(bpx_ebit_marge)),INDEX(bpy_ebit_marge,COUNT(bpx_ebit_marge)),INDEX(bpy_ebit_marge,MATCH(M8,bpx_ebit_marge,1))+(M8-INDEX(bpx_ebit_marge,MATCH(M8,bpx_ebit_marge,1)))/(INDEX(bpx_ebit_marge,MATCH(M8,bpx_ebit_marge,1)+1)-INDEX(bpx_ebit_marge,MATCH(M8,bpx_ebit_marge,1)))*(INDEX(bpy_ebit_marge,MATCH(M8,bpx_ebit_marge,1)+1)-INDEX(bpy_ebit_marge,MATCH(M8,bpx_ebit_marge,1)))))) | O8: =IF(ISNUMBER(N8),$B8*N8,0) | P8: =IF(Kennzahlen!G41="","",Kennzahlen!G41) | Q8: =IF(NOT(ISNUMBER(P8)),"",IF(P8<=INDEX(bpx_ebit_marge,1),INDEX(bpy_ebit_marge,1),IF(P8>=INDEX(bpx_ebit_marge,COUNT(bpx_ebit_marge)),INDEX(bpy_ebit_marge,COUNT(bpx_ebit_marge)),INDEX(bpy_ebit_marge,MATCH(P8,bpx_ebit_marge,1))+(P8-INDEX(bpx_ebit_marge,MATCH(P8,bpx_ebit_marge,1)))/(INDEX(bpx_ebit_marge,MATCH(P8,bpx_ebit_marge,1)+1)-INDEX(bpx_ebit_marge,MATCH(P8,bpx_ebit_marge,1)))*(INDEX(bpy_ebit_marge,MATCH(P8,bpx_ebit_marge,1)+1)-INDEX(bpy_ebit_marge,MATCH(P8,bpx_ebit_marge,1)))))) | R8: =IF(ISNUMBER(Q8),$B8*Q8,0) | S8: =IF(Kennzahlen!H41="","",Kennzahlen!H41) | T8: =IF(NOT(ISNUMBER(S8)),"",IF(S8<=INDEX(bpx_ebit_marge,1),INDEX(bpy_ebit_marge,1),IF(S8>=INDEX(bpx_ebit_marge,COUNT(bpx_ebit_marge)),INDEX(bpy_ebit_marge,COUNT(bpx_ebit_marge)),INDEX(bpy_ebit_marge,MATCH(S8,bpx_ebit_marge,1))+(S8-INDEX(bpx_ebit_marge,MATCH(S8,bpx_ebit_marge,1)))/(INDEX(bpx_ebit_marge,MATCH(S8,bpx_ebit_marge,1)+1)-INDEX(bpx_ebit_marge,MATCH(S8,bpx_ebit_marge,1)))*(INDEX(bpy_ebit_marge,MATCH(S8,bpx_ebit_marge,1)+1)-INDEX(bpy_ebit_marge,MATCH(S8,bpx_ebit_marge,1)))))) | U8: =IF(ISNUMBER(T8),$B8*T8,0) | V8: =IF(Kennzahlen!I41="","",Kennzahlen!I41) | W8: =IF(NOT(ISNUMBER(V8)),"",IF(V8<=INDEX(bpx_ebit_marge,1),INDEX(bpy_ebit_marge,1),IF(V8>=INDEX(bpx_ebit_marge,COUNT(bpx_ebit_marge)),INDEX(bpy_ebit_marge,COUNT(bpx_ebit_marge)),INDEX(bpy_ebit_marge,MATCH(V8,bpx_ebit_marge,1))+(V8-INDEX(bpx_ebit_marge,MATCH(V8,bpx_ebit_marge,1)))/(INDEX(bpx_ebit_marge,MATCH(V8,bpx_ebit_marge,1)+1)-INDEX(bpx_ebit_marge,MATCH(V8,bpx_ebit_marge,1)))*(INDEX(bpy_ebit_marge,MATCH(V8,bpx_ebit_marge,1)+1)-INDEX(bpy_ebit_marge,MATCH(V8,bpx_ebit_marge,1)))))) | X8: =IF(ISNUMBER(W8),$B8*W8,0)
A9: Liquiditaet 2. Grades | B9: 0.08 | C9: percent | D9: =IF(Kennzahlen!C44="","",Kennzahlen!C44) | E9: =IF(NOT(ISNUMBER(D9)),"",IF(D9<=INDEX(bpx_liquiditaet_2_grades,1),INDEX(bpy_liquiditaet_2_grades,1),IF(D9>=INDEX(bpx_liquiditaet_2_grades,COUNT(bpx_liquiditaet_2_grades)),INDEX(bpy_liquiditaet_2_grades,COUNT(bpx_liquiditaet_2_grades)),INDEX(bpy_liquiditaet_2_grades,MATCH(D9,bpx_liquiditaet_2_grades,1))+(D9-INDEX(bpx_liquiditaet_2_grades,MATCH(D9,bpx_liquiditaet_2_grades,1)))/(INDEX(bpx_liquiditaet_2_grades,MATCH(D9,bpx_liquiditaet_2_grades,1)+1)-INDEX(bpx_liquiditaet_2_grades,MATCH(D9,bpx_liquiditaet_2_grades,1)))*(INDEX(bpy_liquiditaet_2_grades,MATCH(D9,bpx_liquiditaet_2_grades,1)+1)-INDEX(bpy_liquiditaet_2_grades,MATCH(D9,bpx_liquiditaet_2_grades,1)))))) | F9: =IF(ISNUMBER(E9),$B9*E9,0) | G9: =IF(Kennzahlen!D44="","",Kennzahlen!D44) | H9: =IF(NOT(ISNUMBER(G9)),"",IF(G9<=INDEX(bpx_liquiditaet_2_grades,1),INDEX(bpy_liquiditaet_2_grades,1),IF(G9>=INDEX(bpx_liquiditaet_2_grades,COUNT(bpx_liquiditaet_2_grades)),INDEX(bpy_liquiditaet_2_grades,COUNT(bpx_liquiditaet_2_grades)),INDEX(bpy_liquiditaet_2_grades,MATCH(G9,bpx_liquiditaet_2_grades,1))+(G9-INDEX(bpx_liquiditaet_2_grades,MATCH(G9,bpx_liquiditaet_2_grades,1)))/(INDEX(bpx_liquiditaet_2_grades,MATCH(G9,bpx_liquiditaet_2_grades,1)+1)-INDEX(bpx_liquiditaet_2_grades,MATCH(G9,bpx_liquiditaet_2_grades,1)))*(INDEX(bpy_liquiditaet_2_grades,MATCH(G9,bpx_liquiditaet_2_grades,1)+1)-INDEX(bpy_liquiditaet_2_grades,MATCH(G9,bpx_liquiditaet_2_grades,1)))))) | I9: =IF(ISNUMBER(H9),$B9*H9,0) | J9: =IF(Kennzahlen!E44="","",Kennzahlen!E44) | K9: =IF(NOT(ISNUMBER(J9)),"",IF(J9<=INDEX(bpx_liquiditaet_2_grades,1),INDEX(bpy_liquiditaet_2_grades,1),IF(J9>=INDEX(bpx_liquiditaet_2_grades,COUNT(bpx_liquiditaet_2_grades)),INDEX(bpy_liquiditaet_2_grades,COUNT(bpx_liquiditaet_2_grades)),INDEX(bpy_liquiditaet_2_grades,MATCH(J9,bpx_liquiditaet_2_grades,1))+(J9-INDEX(bpx_liquiditaet_2_grades,MATCH(J9,bpx_liquiditaet_2_grades,1)))/(INDEX(bpx_liquiditaet_2_grades,MATCH(J9,bpx_liquiditaet_2_grades,1)+1)-INDEX(bpx_liquiditaet_2_grades,MATCH(J9,bpx_liquiditaet_2_grades,1)))*(INDEX(bpy_liquiditaet_2_grades,MATCH(J9,bpx_liquiditaet_2_grades,1)+1)-INDEX(bpy_liquiditaet_2_grades,MATCH(J9,bpx_liquiditaet_2_grades,1)))))) | L9: =IF(ISNUMBER(K9),$B9*K9,0) | M9: =IF(Kennzahlen!F44="","",Kennzahlen!F44) | N9: =IF(NOT(ISNUMBER(M9)),"",IF(M9<=INDEX(bpx_liquiditaet_2_grades,1),INDEX(bpy_liquiditaet_2_grades,1),IF(M9>=INDEX(bpx_liquiditaet_2_grades,COUNT(bpx_liquiditaet_2_grades)),INDEX(bpy_liquiditaet_2_grades,COUNT(bpx_liquiditaet_2_grades)),INDEX(bpy_liquiditaet_2_grades,MATCH(M9,bpx_liquiditaet_2_grades,1))+(M9-INDEX(bpx_liquiditaet_2_grades,MATCH(M9,bpx_liquiditaet_2_grades,1)))/(INDEX(bpx_liquiditaet_2_grades,MATCH(M9,bpx_liquiditaet_2_grades,1)+1)-INDEX(bpx_liquiditaet_2_grades,MATCH(M9,bpx_liquiditaet_2_grades,1)))*(INDEX(bpy_liquiditaet_2_grades,MATCH(M9,bpx_liquiditaet_2_grades,1)+1)-INDEX(bpy_liquiditaet_2_grades,MATCH(M9,bpx_liquiditaet_2_grades,1)))))) | O9: =IF(ISNUMBER(N9),$B9*N9,0) | P9: =IF(Kennzahlen!G44="","",Kennzahlen!G44) | Q9: =IF(NOT(ISNUMBER(P9)),"",IF(P9<=INDEX(bpx_liquiditaet_2_grades,1),INDEX(bpy_liquiditaet_2_grades,1),IF(P9>=INDEX(bpx_liquiditaet_2_grades,COUNT(bpx_liquiditaet_2_grades)),INDEX(bpy_liquiditaet_2_grades,COUNT(bpx_liquiditaet_2_grades)),INDEX(bpy_liquiditaet_2_grades,MATCH(P9,bpx_liquiditaet_2_grades,1))+(P9-INDEX(bpx_liquiditaet_2_grades,MATCH(P9,bpx_liquiditaet_2_grades,1)))/(INDEX(bpx_liquiditaet_2_grades,MATCH(P9,bpx_liquiditaet_2_grades,1)+1)-INDEX(bpx_liquiditaet_2_grades,MATCH(P9,bpx_liquiditaet_2_grades,1)))*(INDEX(bpy_liquiditaet_2_grades,MATCH(P9,bpx_liquiditaet_2_grades,1)+1)-INDEX(bpy_liquiditaet_2_grades,MATCH(P9,bpx_liquiditaet_2_grades,1)))))) | R9: =IF(ISNUMBER(Q9),$B9*Q9,0) | S9: =IF(Kennzahlen!H44="","",Kennzahlen!H44) | T9: =IF(NOT(ISNUMBER(S9)),"",IF(S9<=INDEX(bpx_liquiditaet_2_grades,1),INDEX(bpy_liquiditaet_2_grades,1),IF(S9>=INDEX(bpx_liquiditaet_2_grades,COUNT(bpx_liquiditaet_2_grades)),INDEX(bpy_liquiditaet_2_grades,COUNT(bpx_liquiditaet_2_grades)),INDEX(bpy_liquiditaet_2_grades,MATCH(S9,bpx_liquiditaet_2_grades,1))+(S9-INDEX(bpx_liquiditaet_2_grades,MATCH(S9,bpx_liquiditaet_2_grades,1)))/(INDEX(bpx_liquiditaet_2_grades,MATCH(S9,bpx_liquiditaet_2_grades,1)+1)-INDEX(bpx_liquiditaet_2_grades,MATCH(S9,bpx_liquiditaet_2_grades,1)))*(INDEX(bpy_liquiditaet_2_grades,MATCH(S9,bpx_liquiditaet_2_grades,1)+1)-INDEX(bpy_liquiditaet_2_grades,MATCH(S9,bpx_liquiditaet_2_grades,1)))))) | U9: =IF(ISNUMBER(T9),$B9*T9,0) | V9: =IF(Kennzahlen!I44="","",Kennzahlen!I44) | W9: =IF(NOT(ISNUMBER(V9)),"",IF(V9<=INDEX(bpx_liquiditaet_2_grades,1),INDEX(bpy_liquiditaet_2_grades,1),IF(V9>=INDEX(bpx_liquiditaet_2_grades,COUNT(bpx_liquiditaet_2_grades)),INDEX(bpy_liquiditaet_2_grades,COUNT(bpx_liquiditaet_2_grades)),INDEX(bpy_liquiditaet_2_grades,MATCH(V9,bpx_liquiditaet_2_grades,1))+(V9-INDEX(bpx_liquiditaet_2_grades,MATCH(V9,bpx_liquiditaet_2_grades,1)))/(INDEX(bpx_liquiditaet_2_grades,MATCH(V9,bpx_liquiditaet_2_grades,1)+1)-INDEX(bpx_liquiditaet_2_grades,MATCH(V9,bpx_liquiditaet_2_grades,1)))*(INDEX(bpy_liquiditaet_2_grades,MATCH(V9,bpx_liquiditaet_2_grades,1)+1)-INDEX(bpy_liquiditaet_2_grades,MATCH(V9,bpx_liquiditaet_2_grades,1)))))) | X9: =IF(ISNUMBER(W9),$B9*W9,0)
A10: Zinsdeckungsgrad (EBIT / Zinsaufwand) | B10: 0.05 | C10: x | D10: =IF(Kennzahlen!C39="","",Kennzahlen!C39) | E10: =IF(NOT(ISNUMBER(D10)),"",IF(D10<=INDEX(bpx_zinsdeckungsgrad,1),INDEX(bpy_zinsdeckungsgrad,1),IF(D10>=INDEX(bpx_zinsdeckungsgrad,COUNT(bpx_zinsdeckungsgrad)),INDEX(bpy_zinsdeckungsgrad,COUNT(bpx_zinsdeckungsgrad)),INDEX(bpy_zinsdeckungsgrad,MATCH(D10,bpx_zinsdeckungsgrad,1))+(D10-INDEX(bpx_zinsdeckungsgrad,MATCH(D10,bpx_zinsdeckungsgrad,1)))/(INDEX(bpx_zinsdeckungsgrad,MATCH(D10,bpx_zinsdeckungsgrad,1)+1)-INDEX(bpx_zinsdeckungsgrad,MATCH(D10,bpx_zinsdeckungsgrad,1)))*(INDEX(bpy_zinsdeckungsgrad,MATCH(D10,bpx_zinsdeckungsgrad,1)+1)-INDEX(bpy_zinsdeckungsgrad,MATCH(D10,bpx_zinsdeckungsgrad,1)))))) | F10: =IF(ISNUMBER(E10),$B10*E10,0) | G10: =IF(Kennzahlen!D39="","",Kennzahlen!D39) | H10: =IF(NOT(ISNUMBER(G10)),"",IF(G10<=INDEX(bpx_zinsdeckungsgrad,1),INDEX(bpy_zinsdeckungsgrad,1),IF(G10>=INDEX(bpx_zinsdeckungsgrad,COUNT(bpx_zinsdeckungsgrad)),INDEX(bpy_zinsdeckungsgrad,COUNT(bpx_zinsdeckungsgrad)),INDEX(bpy_zinsdeckungsgrad,MATCH(G10,bpx_zinsdeckungsgrad,1))+(G10-INDEX(bpx_zinsdeckungsgrad,MATCH(G10,bpx_zinsdeckungsgrad,1)))/(INDEX(bpx_zinsdeckungsgrad,MATCH(G10,bpx_zinsdeckungsgrad,1)+1)-INDEX(bpx_zinsdeckungsgrad,MATCH(G10,bpx_zinsdeckungsgrad,1)))*(INDEX(bpy_zinsdeckungsgrad,MATCH(G10,bpx_zinsdeckungsgrad,1)+1)-INDEX(bpy_zinsdeckungsgrad,MATCH(G10,bpx_zinsdeckungsgrad,1)))))) | I10: =IF(ISNUMBER(H10),$B10*H10,0) | J10: =IF(Kennzahlen!E39="","",Kennzahlen!E39) | K10: =IF(NOT(ISNUMBER(J10)),"",IF(J10<=INDEX(bpx_zinsdeckungsgrad,1),INDEX(bpy_zinsdeckungsgrad,1),IF(J10>=INDEX(bpx_zinsdeckungsgrad,COUNT(bpx_zinsdeckungsgrad)),INDEX(bpy_zinsdeckungsgrad,COUNT(bpx_zinsdeckungsgrad)),INDEX(bpy_zinsdeckungsgrad,MATCH(J10,bpx_zinsdeckungsgrad,1))+(J10-INDEX(bpx_zinsdeckungsgrad,MATCH(J10,bpx_zinsdeckungsgrad,1)))/(INDEX(bpx_zinsdeckungsgrad,MATCH(J10,bpx_zinsdeckungsgrad,1)+1)-INDEX(bpx_zinsdeckungsgrad,MATCH(J10,bpx_zinsdeckungsgrad,1)))*(INDEX(bpy_zinsdeckungsgrad,MATCH(J10,bpx_zinsdeckungsgrad,1)+1)-INDEX(bpy_zinsdeckungsgrad,MATCH(J10,bpx_zinsdeckungsgrad,1)))))) | L10: =IF(ISNUMBER(K10),$B10*K10,0) | M10: =IF(Kennzahlen!F39="","",Kennzahlen!F39) | N10: =IF(NOT(ISNUMBER(M10)),"",IF(M10<=INDEX(bpx_zinsdeckungsgrad,1),INDEX(bpy_zinsdeckungsgrad,1),IF(M10>=INDEX(bpx_zinsdeckungsgrad,COUNT(bpx_zinsdeckungsgrad)),INDEX(bpy_zinsdeckungsgrad,COUNT(bpx_zinsdeckungsgrad)),INDEX(bpy_zinsdeckungsgrad,MATCH(M10,bpx_zinsdeckungsgrad,1))+(M10-INDEX(bpx_zinsdeckungsgrad,MATCH(M10,bpx_zinsdeckungsgrad,1)))/(INDEX(bpx_zinsdeckungsgrad,MATCH(M10,bpx_zinsdeckungsgrad,1)+1)-INDEX(bpx_zinsdeckungsgrad,MATCH(M10,bpx_zinsdeckungsgrad,1)))*(INDEX(bpy_zinsdeckungsgrad,MATCH(M10,bpx_zinsdeckungsgrad,1)+1)-INDEX(bpy_zinsdeckungsgrad,MATCH(M10,bpx_zinsdeckungsgrad,1)))))) | O10: =IF(ISNUMBER(N10),$B10*N10,0) | P10: =IF(Kennzahlen!G39="","",Kennzahlen!G39) | Q10: =IF(NOT(ISNUMBER(P10)),"",IF(P10<=INDEX(bpx_zinsdeckungsgrad,1),INDEX(bpy_zinsdeckungsgrad,1),IF(P10>=INDEX(bpx_zinsdeckungsgrad,COUNT(bpx_zinsdeckungsgrad)),INDEX(bpy_zinsdeckungsgrad,COUNT(bpx_zinsdeckungsgrad)),INDEX(bpy_zinsdeckungsgrad,MATCH(P10,bpx_zinsdeckungsgrad,1))+(P10-INDEX(bpx_zinsdeckungsgrad,MATCH(P10,bpx_zinsdeckungsgrad,1)))/(INDEX(bpx_zinsdeckungsgrad,MATCH(P10,bpx_zinsdeckungsgrad,1)+1)-INDEX(bpx_zinsdeckungsgrad,MATCH(P10,bpx_zinsdeckungsgrad,1)))*(INDEX(bpy_zinsdeckungsgrad,MATCH(P10,bpx_zinsdeckungsgrad,1)+1)-INDEX(bpy_zinsdeckungsgrad,MATCH(P10,bpx_zinsdeckungsgrad,1)))))) | R10: =IF(ISNUMBER(Q10),$B10*Q10,0) | S10: =IF(Kennzahlen!H39="","",Kennzahlen!H39) | T10: =IF(NOT(ISNUMBER(S10)),"",IF(S10<=INDEX(bpx_zinsdeckungsgrad,1),INDEX(bpy_zinsdeckungsgrad,1),IF(S10>=INDEX(bpx_zinsdeckungsgrad,COUNT(bpx_zinsdeckungsgrad)),INDEX(bpy_zinsdeckungsgrad,COUNT(bpx_zinsdeckungsgrad)),INDEX(bpy_zinsdeckungsgrad,MATCH(S10,bpx_zinsdeckungsgrad,1))+(S10-INDEX(bpx_zinsdeckungsgrad,MATCH(S10,bpx_zinsdeckungsgrad,1)))/(INDEX(bpx_zinsdeckungsgrad,MATCH(S10,bpx_zinsdeckungsgrad,1)+1)-INDEX(bpx_zinsdeckungsgrad,MATCH(S10,bpx_zinsdeckungsgrad,1)))*(INDEX(bpy_zinsdeckungsgrad,MATCH(S10,bpx_zinsdeckungsgrad,1)+1)-INDEX(bpy_zinsdeckungsgrad,MATCH(S10,bpx_zinsdeckungsgrad,1)))))) | U10: =IF(ISNUMBER(T10),$B10*T10,0) | V10: =IF(Kennzahlen!I39="","",Kennzahlen!I39) | W10: =IF(NOT(ISNUMBER(V10)),"",IF(V10<=INDEX(bpx_zinsdeckungsgrad,1),INDEX(bpy_zinsdeckungsgrad,1),IF(V10>=INDEX(bpx_zinsdeckungsgrad,COUNT(bpx_zinsdeckungsgrad)),INDEX(bpy_zinsdeckungsgrad,COUNT(bpx_zinsdeckungsgrad)),INDEX(bpy_zinsdeckungsgrad,MATCH(V10,bpx_zinsdeckungsgrad,1))+(V10-INDEX(bpx_zinsdeckungsgrad,MATCH(V10,bpx_zinsdeckungsgrad,1)))/(INDEX(bpx_zinsdeckungsgrad,MATCH(V10,bpx_zinsdeckungsgrad,1)+1)-INDEX(bpx_zinsdeckungsgrad,MATCH(V10,bpx_zinsdeckungsgrad,1)))*(INDEX(bpy_zinsdeckungsgrad,MATCH(V10,bpx_zinsdeckungsgrad,1)+1)-INDEX(bpy_zinsdeckungsgrad,MATCH(V10,bpx_zinsdeckungsgrad,1)))))) | X10: =IF(ISNUMBER(W10),$B10*W10,0)
